{"trial_id": "03", "hyperparameters": {"space": [{"class_name": "Choice", "config": {"name": "filters", "default": 16, "conditions": [], "values": [16, 32, 64], "ordered": true}}, {"class_name": "Choice", "config": {"name": "kernel_size", "default": 2, "conditions": [], "values": [2, 3, 4, 5], "ordered": true}}, {"class_name": "Choice", "config": {"name": "activation", "default": "relu", "conditions": [], "values": ["relu", "tanh", "sigmoid"], "ordered": false}}, {"class_name": "Choice", "config": {"name": "learning_rate", "default": 0.01, "conditions": [], "values": [0.01, 0.001, 0.0001, 1e-05], "ordered": true}}, {"class_name": "Choice", "config": {"name": "loss", "default": "mse", "conditions": [], "values": ["mse", "mae"], "ordered": false}}], "values": {"filters": 64, "kernel_size": 2, "activation": "sigmoid", "learning_rate": 1e-05, "loss": "mae"}}, "metrics": {"metrics": {}}, "score": null, "best_step": 0, "status": "FAILED", "message": "Traceback (most recent call last):\n  File \"/srv/conda/envs/notebook/lib/python3.10/site-packages/keras_tuner/src/engine/base_tuner.py\", line 273, in _try_run_and_update_trial\n    self._run_and_update_trial(trial, *fit_args, **fit_kwargs)\n  File \"/srv/conda/envs/notebook/lib/python3.10/site-packages/keras_tuner/src/engine/base_tuner.py\", line 238, in _run_and_update_trial\n    results = self.run_trial(trial, *fit_args, **fit_kwargs)\n  File \"/srv/conda/envs/notebook/lib/python3.10/site-packages/keras_tuner/src/engine/tuner.py\", line 314, in run_trial\n    obj_value = self._build_and_fit_model(trial, *args, **copied_kwargs)\n  File \"/srv/conda/envs/notebook/lib/python3.10/site-packages/keras_tuner/src/engine/tuner.py\", line 233, in _build_and_fit_model\n    results = self.hypermodel.fit(hp, model, *args, **kwargs)\n  File \"/srv/conda/envs/notebook/lib/python3.10/site-packages/keras_tuner/src/engine/hypermodel.py\", line 149, in fit\n    return model.fit(*args, **kwargs)\n  File \"/srv/conda/envs/notebook/lib/python3.10/site-packages/keras/utils/traceback_utils.py\", line 70, in error_handler\n    raise e.with_traceback(filtered_tb) from None\n  File \"/srv/conda/envs/notebook/lib/python3.10/site-packages/keras/engine/data_adapter.py\", line 1668, in train_validation_split\n    raise ValueError(\nValueError: `validation_split` is only supported for Tensors or NumPy arrays, found following types in the input: [<class 'xarray.core.dataarray.DataArray'>, <class 'xarray.core.dataarray.DataArray'>, <class 'xarray.core.dataarray.DataArray'>, <class 'xarray.core.dataarray.DataArray'>, <class 'xarray.core.dataarray.DataArray'>, <class 'xarray.core.dataarray.DataArray'>, <class 'xarray.core.dataarray.DataArray'>, <class 'xarray.core.dataarray.DataArray'>, <class 'xarray.core.dataarray.DataArray'>]\n"}